✅ Données chargées: 3185 aliments
 * Serving Flask app 'app'
 * Debug mode: on
WARNING: This is a development server. Do not use it in a production deployment. Use a production WSGI server instead.
 * Running on all addresses (0.0.0.0)
 * Running on http://127.0.0.1:3002
 * Running on http://192.168.1.133:3002
Press CTRL+C to quit
 * Restarting with watchdog (inotify)
Traceback (most recent call last):
  File "/home/amine/Documents/WORK/Nutritio/Webapp/app.py", line 162, in <module>
    app.run(debug=True, host='0.0.0.0', port=3002)
  File "/home/amine/.local/lib/python3.10/site-packages/flask/app.py", line 615, in run
    run_simple(t.cast(str, host), port, self, **options)
  File "/usr/local/lib/python3.10/dist-packages/werkzeug-3.0.1-py3.10.egg/werkzeug/serving.py", line 1099, in run_simple
    run_with_reloader(
  File "/usr/local/lib/python3.10/dist-packages/werkzeug-3.0.1-py3.10.egg/werkzeug/_reloader.py", line 456, in run_with_reloader
    sys.exit(reloader.restart_with_reloader())
  File "/usr/local/lib/python3.10/dist-packages/werkzeug-3.0.1-py3.10.egg/werkzeug/_reloader.py", line 273, in restart_with_reloader
    exit_code = subprocess.call(args, env=new_environ, close_fds=False)
  File "/usr/lib/python3.10/subprocess.py", line 345, in call
    with Popen(*popenargs, **kwargs) as p:
  File "/usr/lib/python3.10/subprocess.py", line 971, in __init__
    self._execute_child(args, executable, preexec_fn, close_fds,
  File "/usr/lib/python3.10/subprocess.py", line 1751, in _execute_child
    self._posix_spawn(args, executable, env, restore_signals,
  File "/usr/lib/python3.10/subprocess.py", line 1696, in _posix_spawn
    self.pid = os.posix_spawn(executable, args, env, **kwargs)
FileNotFoundError: [Errno 2] No such file or directory: '/home/amine/Documents/WORK/Nutritio/Webapp/Cursor-1.1.3-x86_64.AppImage'
